Workbook

Sheet Summary
A1: Temporary Relocation Areas (TRAs) in South Africa – compiled from 2022–2026 online sources
A2: Compiled 27 Sep 2026. Includes TRAs, transit camps, TRUs and temporary emergency accommodation (TEA) sites. Coordinates are estimates from named landmarks unless marked 'Published'.
A4: Province | B4: Sites listed | C4: Active / active-variant | D4: Uncertain status
A5: Western Cape | B5: =COUNTIF('Existing TRAs'!$B:$B,A5) -> 24 | C5: =COUNTIFS('Existing TRAs'!$B:$B,A5,'Existing TRAs'!$L:$L,"Active*") -> 18 | D5: =COUNTIFS('Existing TRAs'!$B:$B,A5,'Existing TRAs'!$L:$L,"Uncertain*") -> 6
A6: KwaZulu-Natal | B6: =COUNTIF('Existing TRAs'!$B:$B,A6) -> 33 | C6: =COUNTIFS('Existing TRAs'!$B:$B,A6,'Existing TRAs'!$L:$L,"Active*") -> 22 | D6: =COUNTIFS('Existing TRAs'!$B:$B,A6,'Existing TRAs'!$L:$L,"Uncertain*") -> 9
A7: Gauteng | B7: =COUNTIF('Existing TRAs'!$B:$B,A7) -> 14 | C7: =COUNTIFS('Existing TRAs'!$B:$B,A7,'Existing TRAs'!$L:$L,"Active*") -> 5 | D7: =COUNTIFS('Existing TRAs'!$B:$B,A7,'Existing TRAs'!$L:$L,"Uncertain*") -> 8
A8: Eastern Cape | B8: =COUNTIF('Existing TRAs'!$B:$B,A8) -> 13 | C8: =COUNTIFS('Existing TRAs'!$B:$B,A8,'Existing TRAs'!$L:$L,"Active*") -> 8 | D8: =COUNTIFS('Existing TRAs'!$B:$B,A8,'Existing TRAs'!$L:$L,"Uncertain*") -> 4
A9: Free State | B9: =COUNTIF('Existing TRAs'!$B:$B,A9) -> 0 | C9: =COUNTIFS('Existing TRAs'!$B:$B,A9,'Existing TRAs'!$L:$L,"Active*") -> 0 | D9: =COUNTIFS('Existing TRAs'!$B:$B,A9,'Existing TRAs'!$L:$L,"Uncertain*") -> 0
A10: Northern Cape | B10: =COUNTIF('Existing TRAs'!$B:$B,A10) -> 0 | C10: =COUNTIFS('Existing TRAs'!$B:$B,A10,'Existing TRAs'!$L:$L,"Active*") -> 0 | D10: =COUNTIFS('Existing TRAs'!$B:$B,A10,'Existing TRAs'!$L:$L,"Uncertain*") -> 0
A11: North West | B11: =COUNTIF('Existing TRAs'!$B:$B,A11) -> 0 | C11: =COUNTIFS('Existing TRAs'!$B:$B,A11,'Existing TRAs'!$L:$L,"Active*") -> 0 | D11: =COUNTIFS('Existing TRAs'!$B:$B,A11,'Existing TRAs'!$L:$L,"Uncertain*") -> 0
A12: Limpopo | B12: =COUNTIF('Existing TRAs'!$B:$B,A12) -> 0 | C12: =COUNTIFS('Existing TRAs'!$B:$B,A12,'Existing TRAs'!$L:$L,"Active*") -> 0 | D12: =COUNTIFS('Existing TRAs'!$B:$B,A12,'Existing TRAs'!$L:$L,"Uncertain*") -> 0
A13: Mpumalanga | B13: =COUNTIF('Existing TRAs'!$B:$B,A13) -> 0 | C13: =COUNTIFS('Existing TRAs'!$B:$B,A13,'Existing TRAs'!$L:$L,"Active*") -> 0 | D13: =COUNTIFS('Existing TRAs'!$B:$B,A13,'Existing TRAs'!$L:$L,"Uncertain*") -> 0
A14: Total | B14: =SUM(B5:B13) -> 84 | C14: =SUM(C5:C13) -> 53 | D14: =SUM(D5:D13) -> 27
A16: Key caveats
A17: • No official national or municipal inventory of TRAs is published. Cape Town's own plans define 'Incremental Development Areas' but name no sites; the Constitutional Court (Bromwell St, Dec 2024) noted the City gave no inventory.
A18: • eThekwini reported 71–72 legacy transit camps (built mainly 2008–2010); ~40–42 remained in 2024, target to clear by end-2026. Most camp names are not published – only those in the news are listed here.
A19: • KZN built ~1,766 Temporary Residential Units (TRUs) after the April 2022 floods, mostly single units on families' own plots (not camps). KSD (Mthatha) similarly placed 1,000+ in-situ TRUs after the June 2025 floods.
A20: • No named TRA sites were found in 2022–26 sources for Free State, Northern Cape, North West, Limpopo or Mpumalanga. This reflects limited coverage, not proof that none exist.
A21: • Research stopped when the session's web-search limit was reached; some candidate sites were not checked (e.g. Cape Town: Kosovo, Sweet Home Farm, Driftsands, Freedom Park, Leonsdale, Nooiensfontein, Masiphumelele; Durban: Richmond Farm, Siyanda, Cato Crest, Welbedacht; Gauteng: Ennerdale, Lehae, Orange Farm, Emfuleni, Mogale).
A22: • Suggested next steps for completeness: PAIA request to municipalities for TRA/IDA/transit-camp lists; eThekwini Human Settlements committee reports; KZN DoHS Annual Performance Plan; WC Provincial Parliament written replies; SAHRC Western Cape TRA engagement (Feb 2025).
A23: • Rows marked [Verified] were re-checked against the source during compilation.

Sheet Existing TRAs
A1: # | B1: Province | C1: Municipality | D1: Site name / aliases | E1: Type | F1: Suburb / landmark | G1: Approx. latitude | H1: Approx. longitude | I1: Coordinate confidence | J1: Established | K1: Size (households / units) | L1: Status | M1: Status detail (latest source) | N1: Latest source date | O1: Source 1 | P1: Source 2
A2: 1 | B2: Western Cape | C2: City of Cape Town | D2: Blikkiesdorp (Symphony Way TRA) | E2: TRA | F2: Delft, Symphony Way, next to Cape Town Intl Airport | G2: -33.981 | H2: 18.631 | I2: Published (Wikipedia) | J2: 2007 | K2: ~1,600 zinc units built; ~1,300 dwellings (2026) | L2: Active | M2: Symphony Way housing project (~3,500 units for Blikkiesdorp, Malawi Camp, Freedom Farm) resumed Mar 2025; some residents moved to subsidy houses. | N2: 2026-07-07 | O2: https://capeargus.co.za/news/2026-07-07-blikkiesdorp-19-years-of-unfulfilled-housing-promises-for-residents/ | P2: https://www.ewn.co.za/2025/03/10/blikkiesdorp-malawi-camp-freedom-farm-residents-excited-to-see-symphony-way-housing-project-resume
A3: 2 | B3: Western Cape | C3: City of Cape Town (provincial site) | D3: Delft TRA 5 / 5.1 | E3: TRA (N2 Gateway) | F3: Delft, N2 Gateway Phase 1 | G3: -33.97 | H3: 18.64 | I3: Estimated (±1–3 km) | J3: 2010 | K3: 1,095 units (~1,070 occupied) | L3: Active | M3: Still occupied after 16 years; flooding and sanitation failures reported Jul 2026. Run by Western Cape Govt. | N3: 2026-07 | O3: https://www.2oceansvibe.com/politics/mnqasela-tra5-housing-wait-july-2026/ | P3: https://www.wcpp.gov.za/?q=node/11843
A4: 3 | B4: Western Cape | C4: City of Cape Town (provincial site) | D4: Delft TRA 6 | E4: TRA (N2 Gateway) | F4: Delft, linked to Joe Slovo / N2 Gateway | G4: -33.97 | H4: 18.64 | I4: Estimated (±1–3 km) | J4: 2013 | K4: 423 units (~374 occupied) | L4: Active | M4: Used as receiving TRA for Southern Corridor programme (2022). Run by Western Cape Govt. | N4: 2022-05-08 | O4: https://iol.co.za/weekend-argus/news/2022-05-08-temporary-housing-rented-out-by-occupants-for-r1-000/ | P4: https://www.wcpp.gov.za/?q=node/11843
A5: 4 | B5: Western Cape | C5: City of Cape Town | D5: Tsunami (former TRA) | E5: Former TRA, now informal settlement | F5: Delft, next to Delft TRAs | G5: -33.975 | H5: 18.625 | I5: Estimated (±1–3 km) | J5: c. 2005–08 (unconfirmed) | K5: ~1,700 shacks (2025) | L5: Active | M5: Development planned; residents resisting relocation (Sep 2025). | N5: 2025-09-12 | O5: https://www.parliament.gov.za/storage/app/media/Pages/2025/12-09-2025_NCOP_Local_Government_Week/day1/2025-local-government-week-site-profiles-eersterivier-delft-and-mfuleni.pdf
A6: 5 | B6: Western Cape | C6: City of Cape Town (provincial site) | D6: Joe Slovo Temporary Housing Area (THA) | E6: TRA | F6: Langa, along Jakes Gerwel Drive | G6: -33.94 | H6: 18.54 | I6: Estimated (±1–3 km) | J6: 2017 | K6: Not reported | L6: Uncertain | M6: For residents who refused Delft move; no status found after Apr 2022. | N6: 2022-04-08 | O6: https://www.wcpp.gov.za/?q=node/11843
A7: 6 | B7: Western Cape | C7: City of Cape Town | D7: Langa 'Old Beer Hall' shipping-container TRA | E7: TRA (containers) | F7: Langa, Lerotholi Avenue | G7: -33.945 | H7: 18.53 | I7: Estimated (±1–3 km) | J7: 2002 | K7: Not reported | L7: Active | M7: Still occupied after 23 years (Apr 2025); City says part of Langa redevelopment, no timeline. | N7: 2025-04 | O7: https://groundup.org.za/article/families-moved-to-shipping-containers-by-city-23-years-ago-live-in-dire-conditions/
A8: 7 | B8: Western Cape | C8: City of Cape Town | D8: Masonwabe TRA | E8: TRA | F8: Gugulethu, NY109, behind Gugulethu police station (former Masonwabe hostel site) | G8: -33.975 | H8: 18.57 | I8: Estimated (±1–3 km) | J8: 2013 | K8: 100+ families (~136 structures) | L8: Active | M8: Jul 2026: City plans to rehouse Masonwabe and Singabalapha (Observatory) residents together on a new Gugulethu site; residents object. [Verified] | N8: 2026-07-30 | O8: https://groundup.org.za/article/gugulethu-residents-lambast-citys-plan-for-them-to-share-land-with-observatory-occupiers/ | P8: https://groundup.org.za/article/families-living-in-temporary-housing-for-over-a-decade-say-city-of-cape-town-has-abandoned-them/
A9: 8 | B9: Western Cape | C9: City of Cape Town | D9: Wolwerivier (emergency housing camp / IDA) | E9: TRA / IDA | F9: North of Dunoon, ~30 km from CBD (off R304/N7 side) | G9: -33.77 | H9: 18.55 | I9: Low – rough estimate | J9: 2015 | K9: ~336 units initially; now overcrowded | L9: Active | M9: Roads, crèche, clinic added after 2021; fires Dec 2023; still offered to evictees (Bromwell St case). | N9: 2024-02-01 | O9: https://groundup.org.za/article/situation-even-worse-now-in-wolwerivier-say-residents/ | P9: https://www.dailymaverick.co.za/article/2024-01-24-wolwerivier-emergency-housing-camp-is-hell-on-earth-32km-from-heart-of-cape-town/
A10: 9 | B10: Western Cape | C10: City of Cape Town | D10: Kampies (emergency housing site) | E10: TRA / IDA | F10: Philippi farming area, ~15 km from CBD | G10: -34 | H10: 18.56 | I10: Estimated (±1–3 km) | J10: pre-2019 | K10: ~109 structures / ~140 families | L10: Active | M10: Offered to Bromwell St evictees (SCA, 2023); criticised in UCT input to SAHRC (Feb 2025). | N10: 2025-02 | O10: https://www.dailymaverick.co.za/article/2023-02-06-supreme-court-of-appeal-finds-cape-town-emergency-housing-programme-in-line-with-constitution/ | P10: https://mkeswell.github.io/UCT_SAHRC_input_original.pdf
A11: 10 | B11: Western Cape | C11: City of Cape Town | D11: Bhekela site / Stock Road TRA (PRASA Central Line relocation) | E11: TRA | F11: Philippi East ('Philippi Wedge'), behind Stock Road transport hub | G11: -34 | H11: 18.585 | I11: Estimated (±1–3 km) | J11: Dec 2023–Feb 2024 | K11: 856–891 households | L11: Active | M11: Poor services (90 toilets, tankered water); protests; awaiting permanent relocation. PRASA/HDA on private land. | N11: 2024-02-28 | O11: https://groundup.org.za/article/temporary-relocation-of-more-than-880-families-from-railway-in-cape-town-completed/ | P11: https://www.dailymaverick.co.za/article/2024-02-28-scopa-grills-city-of-cape-town-on-relocation-of-prasas-central-line-occupiers/
A12: 11 | B12: Western Cape | C12: City of Cape Town | D12: Bosasa TRA (old site) | E12: TRA | F12: Mfuleni, ~30 km from CBD | G12: -34.01 | H12: 18.69 | I12: Estimated (±1–3 km) | J12: c. 2009–10 | K12: 150 extra units added 2020 | L12: Active | M12: Cited as active in UCT SAHRC input (Feb 2025); limited transport, high crime. | N12: 2025-02 | O12: https://mkeswell.github.io/UCT_SAHRC_input_original.pdf | P12: https://groundup.org.za/article/mfuleni-residents-are-tired-of-seeing-the-city-relocate-residents-from-other-townships/
A13: 12 | B13: Western Cape | C13: City of Cape Town | D13: Bosasa Link (Mfuleni Emergency Housing Development) | E13: Emergency housing / TRA | F13: Mfuleni, between Old Faure Rd (M49) and Spine Rd ext. (M32) | G13: -34.02 | H13: 18.7 | I13: Estimated (±1–3 km) | J13: 2024 | K13: 713–756 serviced sites | L13: Active | M13: Receiving MyCiTi-displaced households and, Aug 2026, ~30 families from Luyolo hall (Gugulethu). Phase 2 due ~Feb 2026. | N13: 2026-08-05 | O13: https://groundup.org.za/article/families-who-occupied-a-cape-town-community-hall-for-eight-years-have-finally-been-moved/ | P13: https://www.news24.com/mixed-emotions-among-bosasa-link-project-residents-as-they-settle-into-new-homes-20240808
A14: 13 | B14: Western Cape | C14: City of Cape Town | D14: Sondela TRA | E14: TRA | F14: Mfuleni, Ward 108 | G14: -34 | H14: 18.69 | I14: Estimated (±1–3 km) | J14: Nov 2023 | K14: ~324 residents | L14: Active | M14: Serviced (water, electricity, toilets); residents moved from flood-prone wetland. | N14: 2023-11-23 | O14: https://novanews.co.za/cityvision/safer-houses-at-temporary-relocation-area-in-mfuleni-cape-town-welcomed-20231123/
A15: 14 | B15: Western Cape | C15: City of Cape Town | D15: Green Point (Khayelitsha) temporary housing site | E15: TRA | F15: Green Point, Khayelitsha | G15: -34.04 | H15: 18.67 | I15: Estimated (±1–3 km) | J15: Dec 2025–Jan 2026 | K15: 40 units (27 stolen, 13 vandalised Jan 2026) | L15: Active / being rebuilt | M15: For households moved off sewer lines (Lansdowne Rd, Site C/SST). | N15: 2026-01 | O15: https://www.dailymaverick.co.za/article/sewerage-maintenance-relocation-of-khayeelitsha-families-delayed-after-vandalism/ | P15: https://groundup.org.za/article/protesters-demand-city-of-cape-town-compensate-them-for-destroying-their-homes-and-damaging-their-belongings/
A16: 15 | B16: Western Cape | C16: City of Cape Town | D16: Wingfield emergency site | E16: Emergency site | F16: Wingfield / Maitland (state land) | G16: -33.915 | H16: 18.51 | I16: Estimated (±1–3 km) | J16: 2020 (Covid) | K16: ~160 refugees | L16: Active – eviction pending | M16: City filed eviction application Jul 2025. | N16: 2025-07-08 | O16: https://groundup.org.za/article/city-of-cape-town-moves-to-evict-refugees-living-at-two-emergency-housing-sites/
A17: 16 | B17: Western Cape | C17: City of Cape Town | D17: Paint City emergency site | E17: Emergency site | F17: Bellville | G17: -33.89 | H17: 18.63 | I17: Estimated (±1–3 km) | J17: 2020 (Covid) | K17: Not reported | L17: Active – eviction pending | M17: City filed eviction application Jul 2025. | N17: 2025-07-08 | O17: https://groundup.org.za/article/city-of-cape-town-moves-to-evict-refugees-living-at-two-emergency-housing-sites/
A18: 17 | B18: Western Cape | C18: City of Cape Town | D18: Delft South emergency housing site | E18: Emergency housing / TRA | F18: Delft South | I18: Not found | J18: Unknown | K18: Not reported | L18: Active (offered) | M18: Offered to Singabalapha occupiers in 2026 (rejected). May overlap with another Delft site. | N18: 2026-07-30 | O18: https://groundup.org.za/article/gugulethu-residents-lambast-citys-plan-for-them-to-share-land-with-observatory-occupiers/
A19: 18 | B19: Western Cape | C19: City of Cape Town | D19: Imizamo Yethu TRAs (Disa, Depot, Triangle) | E19: TRA | F19: Hout Bay; 'Triangle' above cemetery on Hout Bay Rd | G19: -34.03 | H19: 18.36 | I19: Estimated (±1–3 km) | J19: Dec 2017 (post-fire) | K19: ~300 households | L19: Uncertain | M19: No 2022–26 source found. | N19: 2019-06 | O19: https://groundup.org.za/article/two-years-survivors-imizamo-yethu-fire-crammed-disused-municipal-buildings/ | P19: https://www.sentinelnews.co.za/news/residents-move-onto-tra-site/
A20: 19 | B20: Western Cape | C20: City of Cape Town | D20: Happy Valley TRA | E20: TRA (decant) | F20: Blackheath / Blue Downs, Wimbledon Rd | G20: -33.97 | H20: 18.7 | I20: Estimated (±1–3 km) | J20: c. 2011–12 | K20: Not reported | L20: Uncertain | M20: Could not confirm TRA still exists (protests Jul 2025). | N20: 2012-02 | O20: https://www.bcid.co.za/happy-valley-housing-development/
A21: 20 | B21: Western Cape | C21: Mossel Bay | D21: KwaNonqaba UISP TRA | E21: TRA (prefab) | F21: KwaNonqaba, Mossel Bay | G21: -34.17 | H21: 22.1 | I21: Estimated (±1–3 km) | J21: 2022–23 | K21: 250 prefab units + 250 storage units | L21: Uncertain | M21: Built for in-situ upgrading; damaged in Aug 2022 protests; occupancy unknown. | N21: 2023-08-16 | O21: https://asla.co.za/project/temporary-relocation-area-tra/ | P21: https://mbuisp.org/homepage/project-overview/tra/
A22: 21 | B22: Western Cape | C22: Stellenbosch | D22: Mountain View TRA | E22: TRA | F22: Jamestown, Stellenbosch | G22: -33.98 | H22: 18.84 | I22: Estimated (±1–3 km) | J22: 2017 | K22: Not reported | L22: Active | M22: Protests May 2026 over site 'becoming an informal settlement'. | N22: 2026-05 | O22: https://www.smfnews.org/protest-erupts-over-use-of-jamestown-as-a-relocation-area/
A23: 22 | B23: Western Cape | C23: Stellenbosch | D23: Kayamandi Northern Extension TRA | E23: TRA (decant) | F23: Kayamandi | G23: -33.92 | H23: 18.85 | I23: Estimated (±1–3 km) | J23: c. 2023–24 | K23: Not reported | L23: Uncertain | M23: Decant site for Zone O / Enkanini / Siyahlala upgrades. | N23: n.d. | O23: https://pmg.org.za/committee-meeting/39912/
A24: 23 | B24: Western Cape | C24: Stellenbosch | D24: Watergang TRA | E24: TRA | F24: Kayamandi | G24: -33.92 | H24: 18.85 | I24: Estimated (±1–3 km) | J24: c. 2007–12 | K24: Not reported | L24: Uncertain | M24: Studied in 2021; no 2022–26 status found. | N24: 2021 | O24: https://www.researchgate.net/publication/351839856_An_Analysis_of_the_Watergang_Temporary_Relocation_Area_in_Kayamandi_Stellenbosch
A25: 24 | B25: Western Cape | C25: Knysna | D25: Khayalethu Bungalows temporary relocation | E25: Decant / TRA | F25: Khayalethu, Knysna | G25: -34.03 | H25: 23.05 | I25: Estimated (±1–3 km) | J25: 2024–26 | K25: 124+ planned; 30 completed | L25: Active | M25: Short-term decant while Phases 2–3 built (2025/26–2026/27). | N25: 2026-02 | O25: https://www.thehda.co.za/knysna-khayalethu-bungalows-housing-intervention/
A26: 25 | B26: KwaZulu-Natal | C26: eThekwini | D26: Zamani transit camp (Malukazi; possibly 'Lindela') | E26: Transit camp | F26: Malukazi, ward 89, near King Zwelithini Stadium (Umlazi/Isipingo Hills) | G26: -29.98 | H26: 30.9 | I26: Estimated (±1–3 km) | J26: 2009 | K26: Hundreds of families | L26: Active | M26: Nov 2024: city says no budget for repairs. | N26: 2024-11-28 | O26: https://groundup.org.za/article/families-relocated-for-2010-world-cup-left-with-overflowing-toilets-flood-damaged-homes-and-broken-promises/
A27: 26 | B27: KwaZulu-Natal | C27: eThekwini | D27: Isipingo transit camp | E27: Transit camp | F27: Between Isipingo and Lotus Park, ward 90 | G27: -29.98 | H27: 30.93 | I27: Estimated (±1–3 km) | J27: c. 2009 | K27: ~750 families (2018); most moved 2022–23 | L27: Being emptied | M27: Residents moved to Cornubia and Kanku Rd project; camp to be demolished when cleared. Current status unconfirmed. | N27: 2023-07-20 | O27: https://www.iol.co.za/dailynews/news/isipingo-transit-camp-residents-demand-answers-on-new-housing-allocation-plan-0297da16-8d67-46d8-b370-8348da2bd879 | P27: https://www.sanews.gov.za/south-africa/new-homes-isipingo-transit-camp-residents
A28: 27 | B28: KwaZulu-Natal | C28: eThekwini | D28: KwaDabeka transit camp | E28: Transit camp | F28: KwaDabeka near Clermont (Dumisani Makhaye Dr) | G28: -29.78 | H28: 30.88 | I28: Estimated (±1–3 km) | J28: 2009 | K28: 609 prefab units | L28: Active | M28: Nov 2023: no land to relocate; repairs considered. | N28: 2023-11-01 | O28: https://groundup.org.za/article/transit-camp-homes-are-falling-apart-says-durban-residents/
A29: 28 | B29: KwaZulu-Natal | C29: eThekwini | D29: Amaoti transit camp | E29: Transit camp | F29: Shellbrook St, Amaoti, Inanda | G29: -29.665 | H29: 30.99 | I29: Estimated (±1–3 km) | J29: c. 2012 | K29: ~360 people | L29: Active | M29: Phased move to Amaoti Cuba project (phase 2 delayed). | N29: 2023-04-04 | O29: https://groundup.org.za/article/living-conditions-at-amaoti-transit-camp-are-inhumane-and-getting-worse-say-residents/ | P29: https://www.dailymaverick.co.za/article/2023-04-04-residents-languish-in-inhumane-ethekwini-transit-camp-11-years-later/
A30: 29 | B30: KwaZulu-Natal | C30: eThekwini | D30: Madamfana transit camp | E30: Transit camp | F30: Ntuzuma | G30: -29.72 | H30: 30.95 | I30: Estimated (±1–3 km) | J30: 2017 | K30: 33 families | L30: Active | M30: Funding applied for 22 units (Sep 2023). | N30: 2023-09-21 | O30: https://groundup.org.za/article/families-have-been-waiting-six-years-to-be-moved-from-durban-transit-camp/
A31: 30 | B31: KwaZulu-Natal | C31: eThekwini | D31: Umbhayi transit camp | E31: Transit camp | F31: Umbhayi, near oThongathi (Tongaat) | G31: -29.56 | H31: 31.11 | I31: Estimated (±1–3 km) | J31: 2019 | K31: 100+ people | L31: Active | M31: Tongaat RDP project (~250 houses) incomplete. | N31: 2024-02-16 | O31: https://groundup.org.za/article/families-stuck-in-transit-camp-as-ethekwini-housing-project-remains-incomplete/
A32: 31 | B32: KwaZulu-Natal | C32: eThekwini | D32: Lindelani transit camp | E32: Transit camp | F32: Lindelani (by Ntuzuma) | G32: -29.7 | H32: 30.96 | I32: Estimated (±1–3 km) | J32: 2019 (flood victims) | K32: Not stated | L32: Active | M32: Poor water & sanitation (Jun 2024). | N32: 2024-06-10 | O32: https://iol.co.za/dailynews/news/2024-06-10-no-power-for-the-forgotten-flood-victims/
A33: 32 | B33: KwaZulu-Natal | C33: eThekwini | D33: eMathinini transit camp (Gwala St) | E33: Transit camp | F33: Lamontville (IOL says ward 75 Inanda – conflicting) | G33: -29.945 | H33: 30.955 | I33: Low – rough estimate | J33: 2007+ | K33: 100+ households (2022) | L33: Active | M33: No electricity (Jun 2024); ~150 residents displaced again by Feb 2025 floods. | N33: 2024-06-10 | O33: https://iol.co.za/dailynews/news/2024-06-10-no-power-for-the-forgotten-flood-victims/ | P33: https://groundup.org.za/article/we-have-been-moved-from-one-place-to-another-says-durban-flood-victim/
A34: 33 | B34: KwaZulu-Natal | C34: eThekwini | D34: Lamontville / Barcelona 2 transit camp | E34: Transit camp | F34: Lamontville | G34: -29.94 | H34: 30.95 | I34: Estimated (±1–3 km) | J34: 2008 | K34: Not stated | L34: Active | M34: Cited as active Aug 2024. | N34: 2024-08-16 | O34: https://iol.co.za/dailynews/news/2024-08-16-siboniso-dumas-grand-plan-to-fully-eradicate-transit-camps/
A35: 34 | B35: KwaZulu-Natal | C35: eThekwini | D35: Foreman Road transit camp | E35: Transit camp | F35: Foreman Rd, Clare Estate / Sherwood | G35: -29.82 | H35: 30.98 | I35: Estimated (±1–3 km) | J35: 2008–09 | K35: 800+ households (2017) | L35: Active (partly burned) | M35: Fire 8 Oct 2023 destroyed 60+ shacks; formal housing project planned. | N35: 2023-10-10 | O35: https://www.groundup.org.za/article/transit-camp-for-fire-victims-burns-down-in-durban/
A36: 35 | B36: KwaZulu-Natal | C36: eThekwini | D36: Congo transit camp | E36: Transit camp | F36: Inanda (residents from Nhlungwane) | G36: -29.68 | H36: 30.94 | I36: Low – rough estimate | J36: 2022 (Apr 2022 floods) | K36: ~250 people | L36: Active | M36: No running water, sanitation or electricity (Jun 2024). | N36: 2024-06-11 | O36: https://allafrica.com/stories/202406110038.html
A37: 36 | B37: KwaZulu-Natal | C37: eThekwini | D37: Mayville transit camp(s) | E37: Transit camp | F37: Mayville / Cato Manor | G37: -29.84 | H37: 30.98 | I37: Estimated (±1–3 km) | J37: Legacy | K37: Not stated | L37: Active (slated for closure) | M37: Named as decommissioning targets Aug 2024. | N37: 2024-08-16 | O37: https://iol.co.za/dailynews/news/2024-08-16-siboniso-dumas-grand-plan-to-fully-eradicate-transit-camps/
A38: 37 | B38: KwaZulu-Natal | C38: eThekwini | D38: Durban Central transit camp(s) | E38: Transit camp | F38: Durban central (unnamed) | I38: Not found | J38: Legacy | K38: Not stated | L38: Active (slated for closure) | M38: Named as decommissioning targets Aug 2024. | N38: 2024-08-16 | O38: https://iol.co.za/dailynews/news/2024-08-16-siboniso-dumas-grand-plan-to-fully-eradicate-transit-camps/
A39: 38 | B39: KwaZulu-Natal | C39: eThekwini | D39: Quarry Heights transit camp | E39: Transit camp | F39: Quarry Heights (near KwaMashu/Newlands) | G39: -29.77 | H39: 30.97 | I39: Low – rough estimate | J39: Legacy | K39: Not stated | L39: Uncertain | M39: Oversight visit 2020; no 2022–26 status found. | N39: 2020-09-28 | O39: https://kznlegislature.gov.za/human-settlements-pc-visits-transit-camps/
A40: 39 | B40: KwaZulu-Natal | C40: eThekwini | D40: White City transit camp | E40: Transit camp | F40: White City (Ntuzuma/KwaMashu) | G40: -29.73 | H40: 30.97 | I40: Low – rough estimate | J40: Legacy | K40: Not stated | L40: Uncertain | M40: Oversight visit 2020; no 2022–26 status found. | N40: 2020-09-28 | O40: https://kznlegislature.gov.za/human-settlements-pc-visits-transit-camps/
...

Sheet Closed, planned & context
A1: Province | B1: Municipality | C1: Site | D1: What happened | E1: Status | F1: Source
A2: Western Cape | B2: George | C2: Thembalethu UISP TRA erven | D2: Land used as TRA, later built on | E2: Probably closed | F2: https://www.george.gov.za/update-on-uisp-project-thembalethu/
A3: Western Cape | B3: Bitou | C3: Bossiesgif temporary housing (proposed) | D3: Residents refused to move, Mar 2026 | E3: Proposed / refused | F3: https://www.theherald.co.za/news/2026-03-26-bossiesgif-residents-march-to-bitou-municipal-offices-over-plan-to-move-them/
A4: KwaZulu-Natal | B4: eThekwini | C4: Point Road building TEA | D4: Families moved to Montclair Lodge Jun 2026; remaining evicted Jul 2026 | E4: Closed | F4: https://groundup.org.za/article/kzn-flood-victims-sleep-outside-after-eviction-from-temporary-accommodation/
A5: KwaZulu-Natal | B5: eThekwini | C5: Bayside Hotel / Impala Flats / Bayview Hall (Feb 2025 floods) | D5: Bayside evicted Jul 2025; moved to Umbilo residence | E5: Closed | F5: https://witness.co.za/news/2025/07/10/durban-flood-victims-left-in-the-cold-after-hotel-eviction/
A6: KwaZulu-Natal | B6: eThekwini | C6: 2022 flood mass-care centres (~135 halls) | D6: All closed by 24 Dec 2022 | E6: Closed | F6: https://www.sanews.gov.za/south-africa/kzn-flood-victims-relocated-new-accommodation
A7: KwaZulu-Natal | B7: eThekwini | C7: Pemilton Ave / Shannon Dr transit camp, Reservoir Hills | D7: Put on hold May 2022 after opposition | E7: Never built | F7: https://www.iol.co.za/thepost/news/reservoir-hills-residents-oppose-ethekwini-municipalitys-plan-to-build-transit-camp-4a66aba6-ff06-4716-b843-427e5f471e4a
A8: KwaZulu-Natal | B8: eThekwini | C8: 17–29 legacy transit camps decommissioned (names not published) | D8: eThekwini says 29 of 71 camps cleared by Jun 2024 | E8: Closed | F8: https://iol.co.za/dailynews/news/2024-06-10-no-power-for-the-forgotten-flood-victims/
A9: Gauteng | B9: City of Johannesburg | C9: 3 Kotze Street shelter | D9: Closed Dec 2023 (structural problems) | E9: Closed | F9: https://www.dailymaverick.co.za/article/2024-10-03-joburg-housing-bid-to-provide-emergency-accommodation-highlights-crisis/
A10: Gauteng | B10: City of Johannesburg | C10: Rabie Ridge / Ivory Park Covid TRUs | D10: Dismantled; land occupied by backyarders from Aug 2023 | E10: Closed | F10: https://groundup.org.za/article/300-families-from-rabie-ridge-go-to-court-to-fight-their-eviction/
A11: Gauteng | B11: City of Johannesburg | C11: Ekuthuleni shelter / Linatex building (older TEAs) | D11: No 2022–26 evidence of use as TEA | E11: Probably closed | F11: https://www.dailymaverick.co.za/article/2025-03-20-court-slams-city-of-johannesburg-for-failing-to-provide-temporary-shelter-to-evicted-residents/
A12: Gauteng | B12: City of Tshwane | C12: Nellmapius Library / Community Hall | D12: Mostly emptied Aug 2024 | E12: Closed / mostly emptied | F12: https://www.citizen.co.za/news/south-africa/displaced-mamelodi-flood-victims-uncertain-what-future-holds/
... A15: Mpumalanga | B15: Emakhazeni | C15: Portion 61 Farm Geluk 348 JT | D15: Court-ordered alternative land for ~65 households (Sep 2025) | E15: Not a TRA (context) | F15: https://www.saflii.org/za/cases/ZAGPPHC/2025/925.html
